<?xml version='1.0' encoding='utf-8'?>
<mujoco model="so102_calibrated">
  <asset>
    <texture type="skybox" builtin="gradient" rgb1="0.3 0.5 0.7" rgb2="0 0 0" width="512" height="3072" />
    <texture type="2d" name="groundplane" builtin="checker" mark="edge" rgb1="0.2 0.18 0.14" rgb2="0.15 0.13 0.11" markrgb="0.25 0.22 0.17" width="1" height="1" />
    <material name="groundplane" texture="groundplane" texuniform="true" texrepeat="5 5" reflectance="0.2" rgba="1 1 1 1" />
  </asset>
  <compiler angle="radian" meshdir="assets" autolimits="true" />
  <option timestep="0.008" iterations="100" tolerance="1e-10" />
  <default>
    <geom solref="0.005 1" solimp="0.95 0.99 0.001" condim="1" />
    <default class="so101_new_calib">
      <joint damping="1" frictionloss="0.1" armature="0.005" />
      <position kp="50" />
      <default class="visual">
        <geom type="mesh" contype="0" conaffinity="0" group="2" />
      </default>
      <default class="collision">
        <geom group="3" contype="1" conaffinity="1" friction="1.5 0.2 0.01" solref="0.02 1" solimp="0.995 0.999 0.0005" condim="6" />
      </default>
    </default>
  </default>
  
  <default>
    <default class="sts3215">
      <geom contype="0" conaffinity="0" />
      <joint damping="2.0" frictionloss="0.052" armature="0.1" />
      
      <position kp="17.8" />
    </default>
    <default class="backlash">
      
      <joint damping="0.01" frictionloss="0" armature="0.01" limited="true" range="-0.008726646259971648 0.008726646259971648" />
    </default>
  </default>
  <asset>
    <mesh file="waveshare_mounting_plate_so101_v2.stl" />
    <mesh file="sts3215_03a_v1.stl" />
    <mesh file="motor_holder_so101_base_v1.stl" />
    <mesh file="wrist_roll_follower_so101_v1.stl" />
    <mesh file="moving_jaw_so101_v1.stl" />
    <mesh file="base_motor_holder_so101_v1.stl" />
    <mesh file="upper_arm_so101_v1.stl" />
    <mesh file="wrist_roll_pitch_so101_v2.stl" />
    <mesh file="under_arm_so101_v1.stl" />
    <mesh file="rotation_pitch_so101_v1.stl" />
    <mesh file="motor_holder_so101_wrist_v1.stl" />
    <mesh file="sts3215_03a_no_horn_v1.stl" />
    <mesh file="base_so101_v2.stl" />
      <mesh file="Board_1.stl" scale="0.001 0.001 0.001" />
      <mesh name="SO102-Cam4sim" file="SO102-Cam4sim.stl" scale="0.001 0.001 0.001" />
    <material name="base_motor_holder_so101_v1_material" rgba="1 1 1 1" />
    <material name="base_so101_v2_material" rgba="1 1 1 1" />
    <material name="sts3215_03a_v1_material" rgba="0.1 0.1 0.1 1" />
    <material name="waveshare_mounting_plate_so101_v2_material" rgba="1 1 1 1" />
    <material name="motor_holder_so101_base_v1_material" rgba="1 1 1 1" />
    <material name="rotation_pitch_so101_v1_material" rgba="1 1 1 1" />
    <material name="upper_arm_so101_v1_material" rgba="1 1 1 1" />
    <material name="under_arm_so101_v1_material" rgba="1 1 1 1" />
    <material name="motor_holder_so101_wrist_v1_material" rgba="1 1 1 1" />
    <material name="sts3215_03a_no_horn_v1_material" rgba="0.1 0.1 0.1 1.0" />
    <material name="wrist_roll_pitch_so101_v2_material" rgba="1 1 1 1" />
    <material name="wrist_roll_follower_so101_v1_material" rgba="1 1 1 1" />
    <material name="wrist_cam_plate_material" rgba="0.2 0.6 1.0 1" />
    <material name="moving_jaw_so101_v1_material" rgba="1 1 1 1" />
    <material name="Board_1_material" rgba="1 1 1 1" />
  </asset>
  <actuator>
    <position class="sts3215" name="shoulder_pan" joint="shoulder_pan" forcerange="-1.5 1.5" ctrlrange="-1.91986 1.91986" />
    <position class="sts3215" name="shoulder_lift" joint="shoulder_lift" forcerange="-1.5 1.5" ctrlrange="-1.74533 1.74533" />
    <position class="sts3215" name="elbow_flex" joint="elbow_flex" forcerange="-1.5 1.5" ctrlrange="-1.69 1.69" />
    <position class="sts3215" name="wrist_flex" joint="wrist_flex" forcerange="-1.5 1.5" ctrlrange="-1.65806 1.65806" />
    <position class="sts3215" name="wrist_roll" joint="wrist_roll" forcerange="-1.5 1.5" ctrlrange="-2.74385 2.84121" />
    <position class="sts3215" name="gripper" joint="gripper" forcerange="-1.5 1.5" ctrlrange="0 1.7" />
  </actuator>
  <equality />

  <keyframe>
    <key
      time="0"
      qpos="0 0 0.0055 1 0 0 0 0 -1.745 1.69 1.3264 1.02588 0"
      qvel="0 0 0 0 0 0 0 0 0 0 0 0"
      ctrl="0 0 0 0 0 0"
    />
  </keyframe>

  <worldbody>
    <geom name="floor" type="plane" size="1 1 0.1" material="groundplane" contype="1" conaffinity="1" friction="1.0 0.01 0.0005" solref="0.02 1" solimp="0.9 0.95 0.003" condim="6" />
    <body name="base" pos="0 0 0.0055" quat="1 0 0 0" childclass="so101_new_calib">
      <joint type="free" name="base_free" />   

      <inertial pos="0.0137179 -5.19711e-05 0.0334843" mass="25.0" fullinertia="0.000114686 0.000136117 0.000130364 -4.59787e-07 4.97151e-06 9.75275e-08" />
      
      <geom type="mesh" class="visual" pos="-0.00636471 -9.94414e-05 -0.0024" quat="0.5 0.5 0.5 0.5" mesh="base_motor_holder_so101_v1" material="base_motor_holder_so101_v1_material" />
      <geom type="mesh" class="collision" pos="-0.00636471 -9.94414e-05 -0.0024" quat="0.5 0.5 0.5 0.5" mesh="base_motor_holder_so101_v1" material="base_motor_holder_so101_v1_material" friction="1.0 0.01 0.0005" solref="0.02 1" solimp="0.9 0.95 0.003" margin="0" condim="6" />
      
      <geom type="mesh" class="visual" pos="-0.00636471 -8.97657e-09 -0.0024" quat="0.5 0.5 0.5 0.5" mesh="base_so101_v2" material="base_so101_v2_material" />
      <geom type="mesh" class="collision" pos="-0.00636471 -8.97657e-09 -0.0024" quat="0.5 0.5 0.5 0.5" mesh="base_so101_v2" material="base_so101_v2_material" friction="1.0 0.01 0.0005" solref="0.02 1" solimp="0.9 0.95 0.003" margin="0" condim="6" />
      
      <geom type="mesh" class="visual" pos="0.0263353 -8.97657e-09 0.0437" quat="1 -2.85511e-16 -9.64433e-17 6.12908e-16" mesh="sts3215_03a_v1" material="sts3215_03a_v1_material" />
      <geom type="mesh" class="collision" pos="0.0263353 -8.97657e-09 0.0437" quat="1 -2.85511e-16 -9.64433e-17 6.12908e-16" mesh="sts3215_03a_v1" material="sts3215_03a_v1_material" friction="1.0 0.01 0.0005" solref="0.02 1" solimp="0.9 0.95 0.003" margin="0" condim="6" />
      
      <geom type="mesh" class="visual" pos="-0.0309827 -0.000199441 0.0474" quat="0.5 0.5 0.5 0.5" mesh="waveshare_mounting_plate_so101_v2" material="waveshare_mounting_plate_so101_v2_material" />
      <geom type="mesh" class="collision" pos="-0.0309827 -0.000199441 0.0474" quat="0.5 0.5 0.5 0.5" mesh="waveshare_mounting_plate_so101_v2" material="waveshare_mounting_plate_so101_v2_material" friction="1.0 0.01 0.0005" solref="0.02 1" solimp="0.9 0.95 0.003" margin="0" condim="6" />
      
      <site group="3" name="baseframe" pos="8.67362e-19 9.55596e-18 3.46945e-18" quat="1 -8.17396e-19 3.78392e-17 2.22045e-16" />
      
      <body name="shoulder" pos="0.0388353 -8.97657e-09 0.0624" quat="0.000000 0.000000 -1.000000 -0.000000">
        
        <joint axis="0 0 1" name="shoulder_pan" type="hinge" range="-1.9198621771937616 1.9198621771937634" class="sts3215" />
        <inertial pos="-0.0307604 -1.66727e-05 -0.0252713" mass="0.100006" fullinertia="8.3759e-05 8.10403e-05 2.39783e-05 7.55525e-08 -1.16342e-06 1.54663e-07" />
        
        <geom type="mesh" class="visual" pos="-0.0303992 0.000422241 -0.0417" quat="0.5 0.5 0.5 -0.5" mesh="sts3215_03a_v1" material="sts3215_03a_v1_material" />
        <geom type="mesh" class="collision" pos="-0.0303992 0.000422241 -0.0417" quat="0.5 0.5 0.5 -0.5" mesh="sts3215_03a_v1" material="sts3215_03a_v1_material" solref="0.02 1" solimp="0.9 0.95 0.003" friction="1.0 0.01 0.0005" margin="0" condim="6" />
        
        <geom type="mesh" class="visual" pos="-0.0675992 -0.000177759 0.0158499" quat="0.5 0.5 -0.5 0.5" mesh="motor_holder_so101_base_v1" material="motor_holder_so101_base_v1_material" />
        <geom type="mesh" class="collision" pos="-0.0675992 -0.000177759 0.0158499" quat="0.5 0.5 -0.5 0.5" mesh="motor_holder_so101_base_v1" material="motor_holder_so101_base_v1_material" />
        
        <geom type="mesh" class="visual" pos="0.0122008 2.22413e-05 0.0464" quat="0.707107 -0.707107 -0 8.3163e-34" mesh="rotation_pitch_so101_v1" material="rotation_pitch_so101_v1_material" />
        <geom type="mesh" class="collision" pos="0.0122008 2.22413e-05 0.0464" quat="0.707107 -0.707107 -0 8.3163e-34" mesh="rotation_pitch_so101_v1" material="rotation_pitch_so101_v1_material" />
        
        <body name="upper_arm" pos="-0.0303992 -0.0182778 -0.0542" quat="0.468543 -0.468543 -0.529591 -0.529591">
          
          <joint axis="0 0 1" name="shoulder_lift" type="hinge" range="-1.7453292519943224 1.7453292519943366" class="sts3215" />
          <inertial pos="-0.0898471 -0.00838224 0.0184089" mass="0.103" fullinertia="4.08002e-05 0.000147318 0.000142487 -1.97819e-05 -4.03016e-08 8.97326e-09" />
          
          <geom type="mesh" class="visual" pos="-0.11257 -0.0155 0.0187" quat="4.56308e-16 -0.707107 0.707107 -1.37383e-16" mesh="sts3215_03a_v1" material="sts3215_03a_v1_material" />
          <geom type="mesh" class="collision" pos="-0.11257 -0.0155 0.0187" quat="4.56308e-16 -0.707107 0.707107 -1.37383e-16" mesh="sts3215_03a_v1" material="sts3215_03a_v1_material" solref="0.02 1" solimp="0.9 0.95 0.003" friction="1.0 0.01 0.0005" margin="0" condim="6" />
          
          <geom type="mesh" class="visual" pos="-0.065085 0.012 0.0182" quat="0 1 0 0" mesh="upper_arm_so101_v1" material="upper_arm_so101_v1_material" />
          <geom type="mesh" class="collision" pos="-0.065085 0.012 0.0182" quat="0 1 0 0" mesh="upper_arm_so101_v1" material="upper_arm_so101_v1_material" />
          
          <body name="lower_arm" pos="-0.11257 -0.028 1.73763e-16" quat="0.751346 -0.000000 -0.000000 0.659909">
            
            
            <joint axis="0 0 1" name="elbow_flex" type="hinge" range="-1.69 1.69" class="sts3215" />
            <inertial pos="-0.0980701 0.00324376 0.0182831" mass="0.104" fullinertia="2.87438e-05 0.000159844 0.00014529 7.41152e-06 1.26409e-06 -4.90188e-08" />
            
            <geom type="mesh" class="visual" pos="-0.0648499 -0.032 0.0182" quat="0 1 0 0" mesh="under_arm_so101_v1" material="under_arm_so101_v1_material" />
            <geom type="mesh" class="collision" pos="-0.0648499 -0.032 0.0182" quat="0 1 0 0" mesh="under_arm_so101_v1" material="under_arm_so101_v1_material" />
            
            <geom type="mesh" class="visual" pos="-0.0648499 -0.032 0.018" quat="3.92687e-16 -1 -1.9186e-15 -6.38378e-16" mesh="motor_holder_so101_wrist_v1" material="motor_holder_so101_wrist_v1_material" />
            <geom type="mesh" class="collision" pos="-0.0648499 -0.032 0.018" quat="3.92687e-16 -1 -1.9186e-15 -6.38378e-16" mesh="motor_holder_so101_wrist_v1" material="motor_holder_so101_wrist_v1_material" />
            
            <geom type="mesh" class="visual" pos="-0.1224 0.0052 0.0187" quat="7.21645e-16 1.56949e-15 1 -3.33067e-16" mesh="sts3215_03a_v1" material="sts3215_03a_v1_material" />
            <geom type="mesh" class="collision" pos="-0.1224 0.0052 0.0187" quat="7.21645e-16 1.56949e-15 1 -3.33067e-16" mesh="sts3215_03a_v1" material="sts3215_03a_v1_material" solref="0.02 1" solimp="0.9 0.95 0.003" friction="1.0 0.01 0.0005" margin="0" condim="6" />
            
            <body name="wrist" pos="-0.1349 0.0052 3.62355e-17" quat="0.720152 0.018155 -0.018858 -0.693322">
              
              <joint axis="0 0 1" name="wrist_flex" type="hinge" range="-1.6580628494556928 1.6580627293335335" class="sts3215" />
              <inertial pos="-0.000103312 -0.0386143 0.0281156" mass="0.079" fullinertia="3.68263e-05 2.5391e-05 2.1e-05 1.7893e-08 -5.28128e-08 3.6412e-06" />
              
              <geom type="mesh" class="visual" pos="8.32667e-17 -0.0424 0.0306" quat="0.5 0.5 0.5 -0.5" mesh="sts3215_03a_no_horn_v1" material="sts3215_03a_no_horn_v1_material" />
              <geom type="mesh" class="collision" pos="8.32667e-17 -0.0424 0.0306" quat="0.5 0.5 0.5 -0.5" mesh="sts3215_03a_no_horn_v1" material="sts3215_03a_no_horn_v1_material" />
              
              <geom type="mesh" class="visual" pos="0 -0.028 0.0181" quat="0.5 -0.5 -0.5 -0.5" mesh="wrist_roll_pitch_so101_v2" material="wrist_roll_pitch_so101_v2_material" />
              <geom type="mesh" class="collision" pos="0 -0.028 0.0181" quat="0.5 -0.5 -0.5 -0.5" mesh="wrist_roll_pitch_so101_v2" material="wrist_roll_pitch_so101_v2_material" />

              

              <body name="gripper" pos="5.55112e-17 -0.0611 0.0181" quat="-0.212631 0.212631 0.674380 0.674380">
                
                <joint axis="0 0 1" name="wrist_roll" type="hinge" range="-2.7438472969992493 2.841206309382605" class="sts3215" />
                <inertial pos="0.000213627 0.000245138 -0.025187" mass="0.087" fullinertia="2.75087e-05 4.33657e-05 3.45059e-05 -3.35241e-07 -5.7352e-06 -5.17847e-08" />
                
                <geom type="mesh" class="visual" pos="0.0077 0.0001 -0.0234" quat="0.707107 -0.707107 1.66015e-15 6.45094e-15" mesh="sts3215_03a_v1" material="sts3215_03a_v1_material" />
                <!-- <geom type="mesh" class="collision" pos="0.0077 0.0001 -0.0234" quat="0.707107 -0.707107 1.66015e-15 6.45094e-15" mesh="sts3215_03a_v1" material="sts3215_03a_v1_material" friction="10.0 0.10 0.01" solref="0.0005 2" solimp="0.9999 0.99998 1e-06" margin="0" condim="6" /> -->

                
                <geom type="mesh" class="visual" pos="8.32667e-17 -0.000218214 0.000949706" quat="0 1 0 0" mesh="SO102-Cam4sim" material="wrist_roll_follower_so101_v1_material" />
                <geom type="mesh" class="collision" pos="8.32667e-17 -0.000218214 0.000949706" quat="0 1 0 0" mesh="SO102-Cam4sim" material="wrist_roll_follower_so101_v1_material" friction="1.0 0.01 0.0005" solref="0.02 1" solimp="0.9 0.95 0.003" margin="0" condim="6" />

                
                <geom name="wrist_cam_plate" type="box" class="visual" pos="0.01 -0.06 -0.005" size="0.015 0.012 0.001" material="wrist_cam_plate_material" quat="0.983255 0.182235 0.000000 0.000000" />


                <site name="wrist_aperture" type="sphere" pos="0.01 -0.06 -0.005" size="0.007" rgba="0 0 0 1" />
                <camera name="wrist" pos="0.01 -0.06 -0.005" quat="0 0 -0.182235 0.983255" fovy="60" mode="fixed" />

                <site group="3" name="gripperframe" pos="-0.0079 -0.000218121 -0.0981274" quat="0.707107 -0 0.707107 -2.37788e-17" />

                <!-- Touch point 1: near gripper body, offset for fingertip contact -->
                <body name="touch_point1" pos="-0.011 0 -0.093">
                  <inertial pos="0 0 0" mass="0.001" fullinertia="1e-08 1e-08 1e-08 0 0 0" />
                  <geom name="touch_point1_geom" type="sphere" class="visual" pos="0 0 0" size="0.003" rgba="1 0 0 1"/>
                  <geom name="touch_point1_geom_collision" type="sphere" class="collision" pos="0 0 0" size="0.001" rgba="1 0 0 1"/>
                  <geom name="gripper_mid_point" type="sphere" class="visual" pos="0.025 0 0" size="0.003" rgba="0 1 1 1" />
                </body>

                <body name="moving_jaw_so101_v1" pos="0.0202 0.0188 -0.0234" quat="0.707086 0.707086 -0.005424 -0.005424">
                  
                  <joint axis="0 0 1" name="gripper" type="hinge" range="-0.23 1.62" class="sts3215" />
                  <inertial pos="-0.00157495 -0.0300244 0.0192755" mass="0.012" fullinertia="6.61427e-06 1.89032e-06 5.28738e-06 -3.19807e-07 -5.90717e-09 -1.09945e-07" />
                  
                  <geom type="mesh" class="visual" pos="-5.55112e-17 -5.55112e-17 0.0189" quat="1 -0 3.00524e-16 -0.11" mesh="moving_jaw_so101_v1" material="moving_jaw_so101_v1_material" />
                  <geom type="mesh" class="collision" pos="-5.55112e-17 -5.55112e-17 0.0189" quat="1 -0 3.00524e-16 -0.11" mesh="moving_jaw_so101_v1" material="moving_jaw_so101_v1_material" friction="1.5 0.2 0.01" solref="0.02 1" solimp="0.9 0.95 0.003" margin="0" condim="3" />

                  <!-- Touch point 2: near moving jaw body, offset for fingertip contact pos="-0.025 -0.071 0.019"> -->
                  <body name="touch_point2" pos="-0.025 -0.060 0.019">
                    <inertial pos="0 0 0" mass="0.001" fullinertia="1e-08 1e-08 1e-08 0 0 0" />
                    <geom name="touch_point2_geom" type="sphere" class="visual" pos="0 0 0" size="0.003" rgba="0 1 0 1"/>
                    <geom name="touch_point2_geom_collision" type="sphere" class="collision" pos="0 0 0" size="0.001" rgba="0 1 0 1"/>
                  </body>
                </body>
              </body>
            </body>
          </body>
        </body>
      </body>
    </body>
  </worldbody>
</mujoco>